[36m[2023-11-01 09:24:11 DEBUG] [cli:114][39m ###############################################################################
[36m[2023-11-01 09:24:11 DEBUG] [cli:115][39m Running command 'run'
[36m[2023-11-01 09:24:11 DEBUG] [cli:119][39m Using settings file '/home/muhammad_kik/.chaostoolkit/settings.yaml'
[36m[2023-11-01 09:24:14 DEBUG] [settings:30][39m The Chaos Toolkit settings file could not be found at '/home/muhammad_kik/.chaostoolkit/settings.yaml'.
[36m[2023-11-01 09:24:14 DEBUG] [__init__:445][39m No controls to apply on 'loader'
[36m[2023-11-01 09:24:14 DEBUG] [__init__:445][39m No controls to apply on 'loader'
[36m[2023-11-01 09:24:14 DEBUG] [caching:24][39m Building activity cache...
[36m[2023-11-01 09:24:14 DEBUG] [caching:35][39m Cached 6 activities
[32m[2023-11-01 09:24:14 INFO] [experiment:58][39m Validating the experiment's syntax
[36m[2023-11-01 09:24:14 DEBUG] [configuration:63][39m Loading configuration...
[36m[2023-11-01 09:24:14 DEBUG] [secret:78][39m Loading secrets...
[36m[2023-11-01 09:24:14 DEBUG] [secret:103][39m Done loading secrets
[32m[2023-11-01 09:24:14 INFO] [experiment:109][39m Experiment looks valid
[36m[2023-11-01 09:24:14 DEBUG] [caching:42][39m Clearing activities cache
[36m[2023-11-01 09:24:14 DEBUG] [cli:314][39m Runtime strategies: hypothesis - before-method-only / rollbacks - default
[36m[2023-11-01 09:24:14 DEBUG] [caching:24][39m Building activity cache...
[36m[2023-11-01 09:24:14 DEBUG] [caching:35][39m Cached 6 activities
[36m[2023-11-01 09:24:14 DEBUG] [configuration:63][39m Loading configuration...
[36m[2023-11-01 09:24:14 DEBUG] [secret:78][39m Loading secrets...
[36m[2023-11-01 09:24:14 DEBUG] [secret:103][39m Done loading secrets
[36m[2023-11-01 09:24:14 DEBUG] [configuration:160][39m Loading dynamic configuration...
[32m[2023-11-01 09:24:14 INFO] [run:369][39m Running experiment: Chaos Load Experiment
[36m[2023-11-01 09:24:14 DEBUG] [__init__:59][39m Initializing controls
[36m[2023-11-01 09:24:14 DEBUG] [__init__:68][39m Initializing control 'Change CHAOS_TYPE env value to steadystate'
[36m[2023-11-01 09:24:14 DEBUG] [__init__:68][39m Initializing control 'Change CHAOS_TYPE env value to off-proxy'
[32m[2023-11-01 09:24:14 INFO] [run:396][39m Steady-state strategy: before-method-only
[32m[2023-11-01 09:24:14 INFO] [run:400][39m Rollbacks strategy: default
[36m[2023-11-01 09:24:14 DEBUG] [__init__:445][39m No controls to apply on 'experiment'
[36m[2023-11-01 09:24:14 DEBUG] [run:563][39m Running steady-state hypothesis before the method
[32m[2023-11-01 09:24:14 INFO] [hypothesis:186][39m Steady state hypothesis: Make sure that load testing has been done & able to prompt every types to server
[36m[2023-11-01 09:24:14 DEBUG] [__init__:445][39m No controls to apply on 'hypothesis'
[36m[2023-11-01 09:24:14 DEBUG] [__init__:455][39m Applying before-control 'Change CHAOS_TYPE env value to steadystate' on 'activity'
[32m[2023-11-01 09:24:14 INFO] [activity:215][39m Probe: Normal load testing log must exists
[36m[2023-11-01 09:24:14 DEBUG] [python:33][39m Activity 'Normal load testing log must exists' loaded from '/usr/lib/python3.8/genericpath.py'
[36m[2023-11-01 09:24:14 DEBUG] [activity:237][39m   => succeeded with 'True'
[36m[2023-11-01 09:24:14 DEBUG] [hypothesis:226][39m allowed tolerance is True
[36m[2023-11-01 09:24:14 DEBUG] [__init__:445][39m No controls to apply on 'activity'
[32m[2023-11-01 09:24:14 INFO] [activity:215][39m Probe: We can request text
[36m[2023-11-01 09:24:19 DEBUG] [activity:237][39m   => succeeded with '{'status': 200, 'headers': {'date': 'Wed, 01 Nov 2023 02:24:12 GMT', 'server': 'uvicorn', 'content-length': '49', 'content-type': 'application/json'}, 'body': {'error': False, 'response': 'Output has been made'}}'
[36m[2023-11-01 09:24:19 DEBUG] [__init__:445][39m No controls to apply on 'activity'
[36m[2023-11-01 09:24:19 DEBUG] [hypothesis:226][39m allowed tolerance is 200
[36m[2023-11-01 09:24:19 DEBUG] [__init__:445][39m No controls to apply on 'activity'
[32m[2023-11-01 09:24:19 INFO] [activity:215][39m Probe: We can request image
[36m[2023-11-01 09:25:19 DEBUG] [activity:294][39m Activity failed
    Traceback (most recent call last):
      File "/usr/lib/python3/dist-packages/urllib3/connectionpool.py", line 421, in _make_request
        six.raise_from(e, None)
      File "<string>", line 3, in raise_from
      File "/usr/lib/python3/dist-packages/urllib3/connectionpool.py", line 416, in _make_request
        httplib_response = conn.getresponse()
      File "/usr/lib/python3.8/http/client.py", line 1348, in getresponse
        response.begin()
      File "/usr/lib/python3.8/http/client.py", line 316, in begin
        version, status, reason = self._read_status()
      File "/usr/lib/python3.8/http/client.py", line 277, in _read_status
        line = str(self.fp.readline(_MAXLINE + 1), "iso-8859-1")
      File "/usr/lib/python3.8/socket.py", line 669, in readinto
        return self._sock.recv_into(b)
    socket.timeout: timed out
    
    During handling of the above exception, another exception occurred:
    
    Traceback (most recent call last):
      File "/home/muhammad_kik/.local/lib/python3.8/site-packages/requests/adapters.py", line 489, in send
        resp = conn.urlopen(
      File "/usr/lib/python3/dist-packages/urllib3/connectionpool.py", line 719, in urlopen
        retries = retries.increment(
      File "/usr/lib/python3/dist-packages/urllib3/util/retry.py", line 400, in increment
        raise six.reraise(type(error), error, _stacktrace)
      File "/usr/lib/python3/dist-packages/six.py", line 703, in reraise
        raise value
      File "/usr/lib/python3/dist-packages/urllib3/connectionpool.py", line 665, in urlopen
        httplib_response = self._make_request(
      File "/usr/lib/python3/dist-packages/urllib3/connectionpool.py", line 423, in _make_request
        self._raise_timeout(err=e, url=url, timeout_value=read_timeout)
      File "/usr/lib/python3/dist-packages/urllib3/connectionpool.py", line 330, in _raise_timeout
        raise ReadTimeoutError(
    urllib3.exceptions.ReadTimeoutError: HTTPConnectionPool(host='138.197.231.156', port=8000): Read timed out. (read timeout=60)
    
    During handling of the above exception, another exception occurred:
    
    Traceback (most recent call last):
      File "/home/muhammad_kik/.local/lib/python3.8/site-packages/chaoslib/provider/http.py", line 59, in run_http_activity
        r = s.request(
      File "/home/muhammad_kik/.local/lib/python3.8/site-packages/requests/sessions.py", line 587, in request
        resp = self.send(prep, **send_kwargs)
      File "/home/muhammad_kik/.local/lib/python3.8/site-packages/requests/sessions.py", line 701, in send
        r = adapter.send(request, **kwargs)
      File "/home/muhammad_kik/.local/lib/python3.8/site-packages/requests/adapters.py", line 578, in send
        raise ReadTimeout(e, request=request)
    requests.exceptions.ReadTimeout: HTTPConnectionPool(host='138.197.231.156', port=8000): Read timed out. (read timeout=60)
    
    During handling of the above exception, another exception occurred:
    
    Traceback (most recent call last):
      File "/home/muhammad_kik/.local/lib/python3.8/site-packages/chaoslib/activity.py", line 291, in run_activity
        result = run_http_activity(activity, configuration, secrets)
      File "/home/muhammad_kik/.local/lib/python3.8/site-packages/chaoslib/provider/http.py", line 98, in run_http_activity
        raise ActivityFailed("activity took too long to complete")
    chaoslib.exceptions.ActivityFailed: activity took too long to complete
[31m[2023-11-01 09:25:19 ERROR] [activity:245][39m   => failed: activity took too long to complete
[36m[2023-11-01 09:25:19 DEBUG] [__init__:445][39m No controls to apply on 'activity'
[33m[2023-11-01 09:25:19 WARNING] [hypothesis:213][39m Probe terminated unexpectedly, so its tolerance could not be validated
[36m[2023-11-01 09:25:19 DEBUG] [__init__:445][39m No controls to apply on 'hypothesis'
[31m[2023-11-01 09:25:19 CRITICAL] [run:579][39m Steady state probe 'We can request image' is not in the given tolerance so failing this experiment
[32m[2023-11-01 09:25:19 INFO] [run:515][39m Experiment ended with status: failed
[36m[2023-11-01 09:25:19 DEBUG] [__init__:445][39m No controls to apply on 'experiment'
[36m[2023-11-01 09:25:19 DEBUG] [__init__:98][39m Cleaning up controls
[36m[2023-11-01 09:25:19 DEBUG] [__init__:107][39m Cleaning up control 'Change CHAOS_TYPE env value to steadystate'
[36m[2023-11-01 09:25:19 DEBUG] [__init__:107][39m Cleaning up control 'Change CHAOS_TYPE env value to off-proxy'
[36m[2023-11-01 09:25:19 DEBUG] [caching:42][39m Clearing activities cache
[36m[2023-11-01 09:25:20 DEBUG] [cli:114][39m ###############################################################################
[36m[2023-11-01 09:25:20 DEBUG] [cli:115][39m Running command 'report'
[36m[2023-11-01 09:25:20 DEBUG] [cli:119][39m Using settings file '/home/muhammad_kik/.chaostoolkit/settings.yaml'
[36m[2023-11-01 09:25:23 DEBUG] [caching:24][39m Building activity cache...
[36m[2023-11-01 09:25:23 DEBUG] [caching:35][39m Cached 6 activities
